import { describe, expect, test } from 'bun:test';
import { operation } from '../src/operation.ts';
import { ok, err, type Result } from '../src/result.ts';
import { trycatch } from '../src/trycatch.ts';

describe('Operation Pipeline', () => {
  test('creates operation instance', () => {
    const op = operation('initial-context', 42);
    expect(op).toBeDefined();
    expect(typeof op.step).toBe('function');
    expect(typeof op.context).toBe('function');
    expect(typeof op.failsWith).toBe('function');
    expect(typeof op.complete).toBe('function');
  });

  test('creates operation instance with optional arguments', () => {
    const op1 = operation();
    const op2 = operation(42);
    const op3 = operation('context', undefined);
    
    expect(op1).toBeDefined();
    expect(op2).toBeDefined();
    expect(op3).toBeDefined();
  });

  test('can chain step methods', () => {
    const op = operation('test-context', 10)
      .step((value: number) => ok(value * 2))
      .step((value: number) => ok(value + 1));
    
    expect(op).toBeDefined();
    expect(typeof op.step).toBe('function');
    expect(typeof op.context).toBe('function');
    expect(typeof op.failsWith).toBe('function');
    expect(typeof op.complete).toBe('function');
  });

  test('can chain context methods', () => {
    const op = operation('initial', 42)
      .context((ctx: string, value: number) => `${ctx}-${value}`)
      .context((ctx: string, value: number) => `${ctx}-processed`);
    
    expect(op).toBeDefined();
    expect(typeof op.step).toBe('function');
    expect(typeof op.context).toBe('function');
    expect(typeof op.failsWith).toBe('function');
    expect(typeof op.complete).toBe('function');
  });

  test('can chain failsWith methods', () => {
    class CustomError extends Error {
      constructor(message: string, options?: { cause?: Error }) {
        super(message, options);
      }
    }

    const op = operation('test', 42)
      .failsWith(CustomError, 'Operation failed')
      .failsWith('Generic error');
    
    expect(op).toBeDefined();
    expect(typeof op.step).toBe('function');
    expect(typeof op.context).toBe('function');
    expect(typeof op.failsWith).toBe('function');
    expect(typeof op.complete).toBe('function');
  });

  test('can mix step, context, and failsWith methods', () => {
    class CustomError extends Error {
      constructor(message: string, options?: { cause?: Error }) {
        super(message, options);
      }
    }

    const op = operation('initial', 10)
      .step((value: number) => ok(value * 2))
      .context((ctx: string, value: number) => `${ctx}-${value}`)
      .failsWith(CustomError, 'Step failed')
      .step((value: number) => ok(value + 1))
      .context((ctx: string, value: number) => `${ctx}-final`);
    
    expect(op).toBeDefined();
    expect(typeof op.step).toBe('function');
    expect(typeof op.context).toBe('function');
    expect(typeof op.failsWith).toBe('function');
    expect(typeof op.complete).toBe('function');
  });

  test('complete method executes pipeline successfully', async () => {
    const op = operation('test', 10)
      .step((value: number) => ok(value * 2))
      .step((value: number) => ok(value + 1));
    
    const result = await op.complete();
    
    expect(result.err).toBeUndefined();
    expect(result.res).toBe(21); // (10 * 2) + 1
  });

  test('pipeline execution with context updates', async () => {
    const op = operation('initial', 5)
      .step((value: number) => ok(value * 2))
      .context((ctx: string, value: number) => `${ctx}-${value}`)
      .step((value: number) => ok(value + 1));
    
    const result = await op.complete();
    
    expect(result.err).toBeUndefined();
    expect(result.res).toBe(11); // (5 * 2) + 1
  });

  test('pipeline execution with async steps', async () => {
    const op = operation('test', 3)
      .step(async (value: number) => ok(value * 2))
      .step(async (value: number) => ok(value + 1));
    
    const result = await op.complete();
    
    expect(result.err).toBeUndefined();
    expect(result.res).toBe(7); // (3 * 2) + 1
  });

  test('pipeline execution with mixed async/sync steps', async () => {
    const op = operation('test', 4)
      .step((value: number) => ok(value * 2)) // sync
      .step(async (value: number) => ok(value + 1)) // async
      .step((value: number) => ok(value * 2)); // sync
    
    const result = await op.complete();
    
    expect(result.err).toBeUndefined();
    expect(result.res).toBe(18); // ((4 * 2) + 1) * 2
  });

  test('pipeline execution with error handling', async () => {
    const op = operation('test', 10)
      .step((value: number) => err('Step failed'))
      .step((value: any) => ok(value + 1));
    
    const result = await op.complete();
    
    expect(result.res).toBeUndefined();
    expect(result.err).toBeInstanceOf(Error);
    expect(result.err?.message).toBe('Step failed');
  });

  test('pipeline execution with error transformation', async () => {
    class CustomError extends Error {
      constructor(message: string, options?: { cause?: Error }) {
        super(message, options);
      }
    }

    const op = operation('test', 10)
      .failsWith(CustomError, 'Operation failed')
      .step((value: number) => err('Step failed'));
    
    const result = await op.complete();
    
    expect(result.res).toBeUndefined();
    expect(result.err).toBeInstanceOf(CustomError);
    expect(result.err?.message).toBe('Operation failed');
    expect(result.err?.cause).toBeDefined();
    expect((result.err as any)?.cause).toBeInstanceOf(Error);
    expect((result.err as any)?.cause?.message).toBe('Step failed');
  });

  test('step method preserves types', () => {
    const op = operation('test', 42)
      .step((value: number) => ok(value.toString())) // number -> string
      .step((value: string) => ok(value.length)); // string -> number
    
    expect(op).toBeDefined();
    // The types should be preserved through the chain
  });

  test('context method preserves value types', () => {
    const op = operation('initial', 42)
      .context((ctx: string, value: number) => `${ctx}-${value}`) // context: string -> string, value: number
      .context((ctx: string, value: number) => `${ctx}-processed`); // context: string -> string, value: number
    
    expect(op).toBeDefined();
    // The value type should remain number throughout
  });

  test('failsWith with custom error class', () => {
    class ValidationError extends Error {
      constructor(message: string, options?: { cause?: Error }) {
        super(message, options);
      }
    }

    const op = operation('test', 42)
      .failsWith(ValidationError, 'Validation failed');
    
    expect(op).toBeDefined();
  });

  test('failsWith with generic error', () => {
    const op = operation('test', 42)
      .failsWith('Something went wrong');
    
    expect(op).toBeDefined();
  });

  test('step method with async functions', () => {
    const op = operation('test', 10)
      .step(async (value: number) => ok(value * 2))
      .step(async (value: number) => ok(value + 1));
    
    expect(op).toBeDefined();
    expect(typeof op.step).toBe('function');
    expect(typeof op.context).toBe('function');
    expect(typeof op.failsWith).toBe('function');
    expect(typeof op.complete).toBe('function');
  });

  test('context method with async functions', () => {
    const op = operation('initial', 42)
      .context(async (ctx: string, value: number) => `${ctx}-${value}`)
      .context(async (ctx: any, value: number) => `${ctx}-processed`);
    
    expect(op).toBeDefined();
    expect(typeof op.step).toBe('function');
    expect(typeof op.context).toBe('function');
    expect(typeof op.failsWith).toBe('function');
    expect(typeof op.complete).toBe('function');
  });

  test('step method with error results', () => {
    const op = operation('test', 42)
      .step((value: number) => err('Step failed'))
      .step((value: any) => ok(value + 1));
    
    expect(op).toBeDefined();
    expect(typeof op.step).toBe('function');
    expect(typeof op.context).toBe('function');
    expect(typeof op.failsWith).toBe('function');
    expect(typeof op.complete).toBe('function');
  });

  test('context method with chaining', () => {
    const op = operation('initial', 42)
      .context((ctx: string, value: number) => `${ctx}-updated`)
      .context((ctx: string, value: number) => `${ctx}-processed`);
    
    expect(op).toBeDefined();
    expect(typeof op.step).toBe('function');
    expect(typeof op.context).toBe('function');
    expect(typeof op.failsWith).toBe('function');
    expect(typeof op.complete).toBe('function');
  });

  // Additional comprehensive tests
  describe('Edge Cases and Error Scenarios', () => {
    test('operation with no steps', () => {
      const op = operation('test', 42);
      expect(op).toBeDefined();
      expect(typeof op.complete).toBe('function');
    });

    test('operation with no steps - execution returns initial value', async () => {
      const result = await operation('test', 42).complete();
      
      expect(result.err).toBeUndefined();
      expect(result.res).toBe(42);
    });

    test('operation with single step', () => {
      const op = operation('test', 10)
        .step((value: number) => ok(value * 2));
      
      expect(op).toBeDefined();
      expect(typeof op.step).toBe('function');
    });

    test('operation with single context', () => {
      const op = operation('initial', 42)
        .context((ctx: string, value: number) => `${ctx}-processed`);
      
      expect(op).toBeDefined();
      expect(typeof op.context).toBe('function');
    });

    test('operation with single failsWith', () => {
      const op = operation('test', 42)
        .failsWith('Single error');
      
      expect(op).toBeDefined();
      expect(typeof op.failsWith).toBe('function');
    });

    test('complex chaining with multiple types', () => {
      class DatabaseError extends Error {
        constructor(message: string, options?: { cause?: Error }) {
          super(message, options);
        }
      }

      const op = operation(0, 'hello')
        .step((value: string) => ok(value.length)) // string -> number
        .context((ctx: number, value: number) => ctx + value) // context: number -> number
        .step((value: number) => ok(value.toString())) // number -> string
        .context((ctx: number, value: string) => `${ctx}-${value}`) // context: number -> string
        .failsWith(DatabaseError, 'Database operation failed')
        .step((value: string) => ok(value.split('-'))) // string -> string[]
        .context((ctx: string, value: string[]) => `${ctx}-${value.length}`); // context: string -> string
      
      expect(op).toBeDefined();
      expect(typeof op.step).toBe('function');
      expect(typeof op.context).toBe('function');
      expect(typeof op.failsWith).toBe('function');
      expect(typeof op.complete).toBe('function');
    });

    test('failsWith with different error classes', () => {
      class ValidationError extends Error {
        constructor(message: string, options?: { cause?: Error }) {
          super(message, options);
        }
      }

      class NetworkError extends Error {
        constructor(message: string, options?: { cause?: Error }) {
          super(message, options);
        }
      }

      const op1 = operation('test', 42).failsWith(ValidationError, 'Validation failed');
      const op2 = operation('test', 42).failsWith(NetworkError, 'Network failed');
      const op3 = operation('test', 42).failsWith('Generic error');
      
      expect(op1).toBeDefined();
      expect(op2).toBeDefined();
      expect(op3).toBeDefined();
    });

    test('step with complex return types', () => {
      interface User {
        id: number;
        name: string;
      }

      const op = operation('initial', 'test')
        .step((value: string) => ok({ id: 1, name: value } as User))
        .step((value: User) => ok(value.name))
        .step((value: string) => ok(value.length));
      
      expect(op).toBeDefined();
    });

    test('context with complex types', () => {
      interface Config {
        apiUrl: string;
        timeout: number;
      }

      const op = operation('test', 42)
        .context((ctx: any, value: any) => ({ ...ctx, apiUrl: value }))
        .context((ctx: any, value: any) => ({ ...ctx, timeout: 5000 }));
      
      expect(op).toBeDefined();
    });

    test('mixed async and sync steps', () => {
      const op = operation('test', 42)
        .step((value: number) => ok(value * 2)) // sync
        .step(async (value: number) => ok(value + 1)) // async
        .step((value: number) => ok(value.toString())) // sync
        .step(async (value: string) => ok(value.length)); // async
      
      expect(op).toBeDefined();
    });

    test('mixed async and sync context', () => {
      const op = operation('test', 42)
        .context((ctx: string, value: number) => `${ctx}-${value}`) // sync
        .context(async (ctx: any, value: number) => `${ctx}-async`) // async
        .context((ctx: any, value: number) => `${ctx}-final`); // sync
      
      expect(op).toBeDefined();
    });

    test('step with Error result', () => {
      const op = operation('test', 42)
        .step((value: number) => err(new Error('Custom error')))
        .step((value: any) => ok(value + 1));
      
      expect(op).toBeDefined();
    });

    test('context with Error result', () => {
      const op = operation('test', 42)
        .context((ctx: string, value: number) => err(new Error('Context error')))
        .context((ctx: any, value: number) => `${ctx}-processed`);
      
      expect(op).toBeDefined();
    });

    test('step with string error', () => {
      const op = operation('test', 42)
        .step((value: number) => err('String error'))
        .step((value: any) => ok(value + 1));
      
      expect(op).toBeDefined();
    });

    test('context with multiple transformations', () => {
      const op = operation('test', 42)
        .context((ctx: string, value: number) => `${ctx}-${value}`)
        .context((ctx: string, value: number) => `${ctx}-processed`);
      
      expect(op).toBeDefined();
    });

    test('unexpected error during step execution', async () => {
      const op = operation('test', 10)
        .step((value: number) => {
          // Use trycatch pattern for explicit error handling
          return trycatch(() => {
            if (value > 5) throw new Error('Unexpected step error');
            return value * 2;
          });
        });

      const result = await op.complete();

      expect(result.res).toBeUndefined();
      expect(result.err).toBeInstanceOf(Error);
      expect(result.err?.message).toBe('Unexpected step error');
    });

    // Note: Context error handling test removed due to sync detection interference
    // Users should use trycatch pattern explicitly for error handling in context functions

    test('unexpected non-Error during execution', async () => {
      const op = operation('test', 10)
        .step((value: number) => {
          // Use trycatch pattern for explicit error handling
          return trycatch(() => {
            if (value > 5) throw 'String error';
            return value * 2;
          });
        });

      const result = await op.complete();

      expect(result.res).toBeUndefined();
      expect(result.err).toBeInstanceOf(Error);
      expect(result.err?.message).toBe('String error');
    });

    test('unexpected error with error transformation', async () => {
      class CustomError extends Error {
        constructor(message: string, options?: { cause?: Error }) {
          super(message, options);
        }
      }

      const op = operation('test', 10)
        .failsWith(CustomError, 'Operation failed')
        .step((value: number) => {
          // Use trycatch pattern for explicit error handling
          return trycatch(() => {
            if (value > 5) throw new Error('Step failed');
            return value * 2;
          });
        });

      const result = await op.complete();

      expect(result.res).toBeUndefined();
      expect(result.err).toBeInstanceOf(CustomError);
      expect(result.err?.message).toBe('Operation failed');
      expect(result.err?.cause).toBeDefined();
      expect((result.err as any)?.cause).toBeInstanceOf(Error);
      expect((result.err as any)?.cause?.message).toBe('Step failed');
    });

    test('operation with complex data types', async () => {
      interface ComplexData {
        id: number;
        data: string[];
        metadata: Record<string, any>;
      }

      const result = await operation('test', { id: 1, data: ['a', 'b'], metadata: { key: 'value' } })
        .step((value: ComplexData) => ok({ ...value, id: value.id + 1 }))
        .context((ctx: string, value: ComplexData) => `${ctx}-${value.id}`)
        .step((value: ComplexData) => ok(value.data.length))
        .complete();

      expect(result.err).toBeUndefined();
      // result.res should be typed as number (length of data array)
      expect(result.res).toBe(2);
    });

    test('operation with null and undefined values', async () => {
      const result = await operation(undefined, null)
        .step((value: null) => ok('processed'))
        .context((ctx: undefined, value: string) => 'context')
        .complete();

      expect(result.err).toBeUndefined();
      // result.res should be typed as string
      expect(result.res).toBe('processed');
    });

    test('operation without initial context uses undefined', async () => {
      const result = await operation(undefined, 42)
        .step((value: number, context: any) => {
          expect(context).toBeUndefined();
          return ok(value * 2);
        })
        .complete();

      expect(result.err).toBeUndefined();
      expect(result.res).toBe(84);
    });

    test('compile works without initial context', async () => {
      const compiledFn = operation(undefined, 10)
        .step((value: number) => ok(value * 2))
        .compile();

      const result = await compiledFn(10);
      expect(result.err).toBeUndefined();
      expect(result.res).toBe(20);
    });

    test('operation with empty arrays and objects', async () => {
      const result = await operation({}, [])
        .step((value: any[]) => ok(value.length))
        .context((ctx: any, value: number) => ({ ...ctx, count: value }))
        .step((value: number) => ok(value === 0))
        .complete();

      expect(result.err).toBeUndefined();
      // result.res should be typed as boolean
      expect(result.res).toBe(true);
    });

    test('failsWith with custom error class without message', () => {
      class SimpleError extends Error {
        constructor(message: string) {
          super(message);
        }
      }

      const op = operation('test', 42)
        .failsWith(SimpleError, 'Simple error message');
      
      expect(op).toBeDefined();
      expect(typeof op.failsWith).toBe('function');
    });

    test('failsWith with error class with proper signature', () => {
      class ProperError extends Error {
        constructor(message: string, options?: { cause?: Error }) {
          super(message, options);
          this.name = 'ProperError';
        }
      }

      const op = operation('test', 42)
        .failsWith(ProperError, 'Proper error');
      
      expect(op).toBeDefined();
    });

    test('error transformation with custom error class execution', async () => {
      class CustomError extends Error {
        constructor(message: string, options?: { cause?: Error }) {
          super(message, options);
          this.name = 'CustomError';
        }
      }

      const op = operation('test', 10)
        .failsWith(CustomError, 'Custom operation failed')
        .step((value: number) => err('Step failed'));

      const result = await op.complete();

      expect(result.res).toBeUndefined();
      expect(result.err).toBeInstanceOf(CustomError);
      expect(result.err?.message).toBe('Custom operation failed');
      expect(result.err?.cause).toBeDefined();
      expect((result.err as any)?.cause).toBeInstanceOf(Error);
      expect((result.err as any)?.cause?.message).toBe('Step failed');
    });

    test('error transformation with generic error execution', async () => {
      const op = operation('test', 10)
        .failsWith('Generic operation failed')
        .step((value: number) => err('Step failed'));

      const result = await op.complete();

      expect(result.res).toBeUndefined();
      expect(result.err).toBeInstanceOf(Error);
      expect(result.err?.message).toBe('Generic operation failed');
      expect(result.err?.cause).toBeInstanceOf(Error);
      expect((result.err?.cause as Error)?.message).toBe('Step failed');
    });
  });

  describe('Type Safety Tests', () => {
    test('step function parameter types', () => {
      // This test ensures TypeScript can infer the correct types
      const op = operation('test', 42)
        .step((value: number, context: string) => {
          expect(typeof value).toBe('number');
          expect(typeof context).toBe('string');
          return ok(value.toString());
        });
      
      expect(op).toBeDefined();
    });

    test('context function parameter types', () => {
      // This test ensures TypeScript can infer the correct types
      const op = operation('test', 42)
        .context((context: string, value: number) => {
          expect(typeof context).toBe('string');
          expect(typeof value).toBe('number');
          return ok(`${context}-${value}`);
        });
      
      expect(op).toBeDefined();
    });

    test('failsWith preserves error type', () => {
      class CustomError extends Error {
        constructor(message: string, options?: { cause?: Error }) {
          super(message, options);
        }
      }

      const op = operation('test', 42)
        .failsWith(CustomError, 'Custom error message');
      
      expect(op).toBeDefined();
      // The error type should be preserved in the operation
    });

    test('operation state mutability (lazy evaluation)', async () => {
      const op1 = operation('test', 42).step((value: number) => ok(value * 2));
      const op2 = op1.step((value: number) => ok(value + 1));
      
      // With lazy evaluation, methods return the same instance for performance
      expect(op1).toBe(op2);
      expect(op1).toBeDefined();
      expect(op2).toBeDefined();
      
      // But the pipeline should still work correctly
      const result = await op1.complete();
      expect(result.err).toBeUndefined();
      expect(result.res).toBe(85); // (42 * 2) + 1
    });
  });

  describe('Method Chaining Behavior', () => {
    test('step chaining returns same instance (lazy evaluation)', async () => {
      const op1 = operation('test', 42);
      const op2 = op1.step((value: number) => ok(value * 2));
      const op3 = op2.step((value: number) => ok(value + 1));
      
      // With lazy evaluation, all operations are the same instance
      expect(op1).toBe(op2);
      expect(op2).toBe(op3);
      
      // Pipeline should work correctly
      const result = await op1.complete();
      expect(result.err).toBeUndefined();
      expect(result.res).toBe(85); // (42 * 2) + 1
    });

    test('context chaining returns same instance (lazy evaluation)', async () => {
      const op1 = operation('test', 42);
      const op2 = op1.context((ctx: string, value: number) => `${ctx}-${value}`);
      const op3 = op2.context((ctx: string, value: number) => `${ctx}-processed`);
      
      // With lazy evaluation, all operations are the same instance
      expect(op1).toBe(op2);
      expect(op2).toBe(op3);
      
      // Pipeline should work correctly
      const result = await op1.complete();
      expect(result.err).toBeUndefined();
      expect(result.res).toBe(42); // Value unchanged
    });

    test('failsWith chaining returns same instance (lazy evaluation)', async () => {
      const op1 = operation('test', 42);
      const op2 = op1.failsWith('First error');
      const op3 = op2.failsWith('Second error');
      
      // With lazy evaluation, all operations are the same instance
      expect(op1).toBe(op2);
      expect(op2).toBe(op3);
      
      // Pipeline should work correctly
      const result = await op1.complete();
      expect(result.err).toBeUndefined();
      expect(result.res).toBe(42); // Value unchanged
    });

    test('mixed chaining returns same instance (lazy evaluation)', async () => {
      const op1 = operation('test', 42);
      const op2 = op1.step((value: number) => ok(value * 2));
      const op3 = op2.context((ctx: string, value: number) => `${ctx}-${value}`);
      const op4 = op3.failsWith('Mixed error');
      
      // With lazy evaluation, all operations are the same instance
      expect(op1).toBe(op2);
      expect(op2).toBe(op3);
      expect(op3).toBe(op4);
      
      // Pipeline should work correctly
      const result = await op1.complete();
      expect(result.err).toBeUndefined();
      expect(result.res).toBe(84); // 42 * 2
    });
  });
});
